2025-07-06 08:23:27,094 - __main__ - INFO - ü§ñ Bot √ßalƒ±≈üƒ±yor...
2025-07-06 08:23:27,270 - __main__ - INFO - Veritabanƒ± baƒülantƒ±sƒ± kuruldu ve tablo hazƒ±r.
2025-07-06 08:23:27,271 - __main__ - INFO - Yapƒ±landƒ±rma dosyalarƒ± (thread_map, keywords_config) belleƒüe y√ºklendi.
2025-07-06 08:24:52,386 - __main__ - INFO - Yeni ilan e≈üle≈ütiriliyor (Esnek E≈üle≈ütirme) -> Pozisyon: 'Moto Kurye', ≈ûehir: 'adana'
2025-07-06 08:24:52,414 - __main__ - INFO - Puanƒ± ge√ßen konular (sƒ±ralƒ±): [('Kurye/Paket√ßi', 120)]
2025-07-06 08:24:52,415 - __main__ - INFO - ≈ûehir e≈üle≈ümesi ba≈üarƒ±lƒ±: 'adana' ≈üehri i√ßin 'adana' anahtarƒ± bulundu.
2025-07-06 08:24:52,415 - __main__ - INFO - ‚úÖ BA≈ûARILI KATEGORƒ∞ E≈ûLE≈ûMESƒ∞: 'Kurye/Paket√ßi' -> 'Kurye/Paket√ßi' (ID: 92)
2025-07-06 08:24:52,585 - __main__ - INFO - Sessiz ilan g√∂nderildi. Chat ID: -1002421814809, Thread ID: None
2025-07-06 08:24:52,691 - __main__ - INFO - Sessiz ilan g√∂nderildi. Chat ID: -1002340487735, Thread ID: None
2025-07-06 08:24:52,813 - __main__ - INFO - Sessiz ilan g√∂nderildi. Chat ID: -1002340487735, Thread ID: 92
2025-07-08 16:40:05,032 - __main__ - INFO - Yeni ilan e≈üle≈ütiriliyor (Esnek E≈üle≈ütirme) -> Pozisyon: 'Barmen', ≈ûehir: 'istanbul'
2025-07-08 16:40:05,041 - __main__ - INFO - Puanƒ± ge√ßen konular (sƒ±ralƒ±): [('Barista/Barmen', 120)]
2025-07-08 16:40:05,041 - __main__ - INFO - ≈ûehir e≈üle≈ümesi ba≈üarƒ±lƒ±: 'istanbul' ≈üehri i√ßin 'istanbul' anahtarƒ± bulundu.
2025-07-08 16:40:05,042 - __main__ - INFO - ‚úÖ BA≈ûARILI KATEGORƒ∞ E≈ûLE≈ûMESƒ∞: 'Barista/Barmen' -> 'Barista/Barmen' (ID: 26)
2025-07-08 16:40:05,467 - __main__ - INFO - Sessiz ilan g√∂nderildi. Chat ID: -1002421814809, Thread ID: None
2025-07-08 16:40:05,773 - __main__ - INFO - Sessiz ilan g√∂nderildi. Chat ID: -1002673178372, Thread ID: None
2025-07-08 16:40:06,137 - __main__ - INFO - Sessiz ilan g√∂nderildi. Chat ID: -1002673178372, Thread ID: 26
2025-07-10 05:25:57,811 - telegram.ext.Application - ERROR - No error handlers are registered, logging exception.
Traceback (most recent call last):
  File "/usr/local/lib/python3.9/site-packages/httpx/_transports/default.py", line 101, in map_httpcore_exceptions
    yield
  File "/usr/local/lib/python3.9/site-packages/httpx/_transports/default.py", line 394, in handle_async_request
    resp = await self._pool.handle_async_request(req)
  File "/usr/local/lib/python3.9/site-packages/httpcore/_async/connection_pool.py", line 256, in handle_async_request
    raise exc from None
  File "/usr/local/lib/python3.9/site-packages/httpcore/_async/connection_pool.py", line 236, in handle_async_request
    response = await connection.handle_async_request(
  File "/usr/local/lib/python3.9/site-packages/httpcore/_async/connection.py", line 103, in handle_async_request
    return await self._connection.handle_async_request(request)
  File "/usr/local/lib/python3.9/site-packages/httpcore/_async/http11.py", line 136, in handle_async_request
    raise exc
  File "/usr/local/lib/python3.9/site-packages/httpcore/_async/http11.py", line 106, in handle_async_request
    ) = await self._receive_response_headers(**kwargs)
  File "/usr/local/lib/python3.9/site-packages/httpcore/_async/http11.py", line 177, in _receive_response_headers
    event = await self._receive_event(timeout=timeout)
  File "/usr/local/lib/python3.9/site-packages/httpcore/_async/http11.py", line 217, in _receive_event
    data = await self._network_stream.read(
  File "/usr/local/lib/python3.9/site-packages/httpcore/_backends/anyio.py", line 37, in read
    return b""
  File "/usr/lib64/python3.9/contextlib.py", line 137, in __exit__
    self.gen.throw(typ, value, traceback)
  File "/usr/local/lib/python3.9/site-packages/httpcore/_exceptions.py", line 14, in map_exceptions
    raise to_exc(exc) from exc
httpcore.ReadError

The above exception was the direct cause of the following exception:

Traceback (most recent call last):
  File "/usr/local/lib/python3.9/site-packages/telegram/request/_httpxrequest.py", line 273, in do_request
    res = await self._client.request(
  File "/usr/local/lib/python3.9/site-packages/httpx/_client.py", line 1540, in request
    return await self.send(request, auth=auth, follow_redirects=follow_redirects)
  File "/usr/local/lib/python3.9/site-packages/httpx/_client.py", line 1629, in send
    response = await self._send_handling_auth(
  File "/usr/local/lib/python3.9/site-packages/httpx/_client.py", line 1657, in _send_handling_auth
    response = await self._send_handling_redirects(
  File "/usr/local/lib/python3.9/site-packages/httpx/_client.py", line 1694, in _send_handling_redirects
    response = await self._send_single_request(request)
  File "/usr/local/lib/python3.9/site-packages/httpx/_client.py", line 1730, in _send_single_request
    response = await transport.handle_async_request(request)
  File "/usr/local/lib/python3.9/site-packages/httpx/_transports/default.py", line 394, in handle_async_request
    resp = await self._pool.handle_async_request(req)
  File "/usr/lib64/python3.9/contextlib.py", line 137, in __exit__
    self.gen.throw(typ, value, traceback)
  File "/usr/local/lib/python3.9/site-packages/httpx/_transports/default.py", line 118, in map_httpcore_exceptions
    raise mapped_exc(message) from exc
httpx.ReadError

The above exception was the direct cause of the following exception:

Traceback (most recent call last):
  File "/usr/local/lib/python3.9/site-packages/telegram/ext/_utils/networkloop.py", line 115, in network_retry_loop
    if not await do_action():
  File "/usr/local/lib/python3.9/site-packages/telegram/ext/_utils/networkloop.py", line 108, in do_action
    return action_cb_task.result()
  File "/usr/local/lib/python3.9/site-packages/telegram/ext/_updater.py", line 335, in polling_action_cb
    updates = await self.bot.get_updates(
  File "/usr/local/lib/python3.9/site-packages/telegram/ext/_extbot.py", line 669, in get_updates
    updates = await super().get_updates(
  File "/usr/local/lib/python3.9/site-packages/telegram/_bot.py", line 4601, in get_updates
    await self._post(
  File "/usr/local/lib/python3.9/site-packages/telegram/_bot.py", line 697, in _post
    return await self._do_post(
  File "/usr/local/lib/python3.9/site-packages/telegram/ext/_extbot.py", line 369, in _do_post
    return await super()._do_post(
  File "/usr/local/lib/python3.9/site-packages/telegram/_bot.py", line 726, in _do_post
    result = await request.post(
  File "/usr/local/lib/python3.9/site-packages/telegram/request/_baserequest.py", line 197, in post
    result = await self._request_wrapper(
  File "/usr/local/lib/python3.9/site-packages/telegram/request/_baserequest.py", line 304, in _request_wrapper
    code, payload = await self.do_request(
  File "/usr/local/lib/python3.9/site-packages/telegram/request/_httpxrequest.py", line 297, in do_request
    raise NetworkError(f"httpx.{err.__class__.__name__}: {err}") from err
telegram.error.NetworkError: httpx.ReadError: 
2025-07-10 14:36:47,822 - telegram.ext.Application - ERROR - No error handlers are registered, logging exception.
Traceback (most recent call last):
  File "/usr/local/lib/python3.9/site-packages/telegram/ext/_utils/networkloop.py", line 115, in network_retry_loop
    if not await do_action():
  File "/usr/local/lib/python3.9/site-packages/telegram/ext/_utils/networkloop.py", line 108, in do_action
    return action_cb_task.result()
  File "/usr/local/lib/python3.9/site-packages/telegram/ext/_updater.py", line 335, in polling_action_cb
    updates = await self.bot.get_updates(
  File "/usr/local/lib/python3.9/site-packages/telegram/ext/_extbot.py", line 669, in get_updates
    updates = await super().get_updates(
  File "/usr/local/lib/python3.9/site-packages/telegram/_bot.py", line 4601, in get_updates
    await self._post(
  File "/usr/local/lib/python3.9/site-packages/telegram/_bot.py", line 697, in _post
    return await self._do_post(
  File "/usr/local/lib/python3.9/site-packages/telegram/ext/_extbot.py", line 369, in _do_post
    return await super()._do_post(
  File "/usr/local/lib/python3.9/site-packages/telegram/_bot.py", line 726, in _do_post
    result = await request.post(
  File "/usr/local/lib/python3.9/site-packages/telegram/request/_baserequest.py", line 197, in post
    result = await self._request_wrapper(
  File "/usr/local/lib/python3.9/site-packages/telegram/request/_baserequest.py", line 355, in _request_wrapper
    raise Conflict(message)
telegram.error.Conflict: Conflict: terminated by other getUpdates request; make sure that only one bot instance is running
2025-07-10 22:25:22,771 - telegram.ext.Application - ERROR - No error handlers are registered, logging exception.
Traceback (most recent call last):
  File "/usr/local/lib/python3.9/site-packages/telegram/ext/_utils/networkloop.py", line 115, in network_retry_loop
    if not await do_action():
  File "/usr/local/lib/python3.9/site-packages/telegram/ext/_utils/networkloop.py", line 108, in do_action
    return action_cb_task.result()
  File "/usr/local/lib/python3.9/site-packages/telegram/ext/_updater.py", line 335, in polling_action_cb
    updates = await self.bot.get_updates(
  File "/usr/local/lib/python3.9/site-packages/telegram/ext/_extbot.py", line 669, in get_updates
    updates = await super().get_updates(
  File "/usr/local/lib/python3.9/site-packages/telegram/_bot.py", line 4601, in get_updates
    await self._post(
  File "/usr/local/lib/python3.9/site-packages/telegram/_bot.py", line 697, in _post
    return await self._do_post(
  File "/usr/local/lib/python3.9/site-packages/telegram/ext/_extbot.py", line 369, in _do_post
    return await super()._do_post(
  File "/usr/local/lib/python3.9/site-packages/telegram/_bot.py", line 726, in _do_post
    result = await request.post(
  File "/usr/local/lib/python3.9/site-packages/telegram/request/_baserequest.py", line 197, in post
    result = await self._request_wrapper(
  File "/usr/local/lib/python3.9/site-packages/telegram/request/_baserequest.py", line 355, in _request_wrapper
    raise Conflict(message)
telegram.error.Conflict: Conflict: terminated by other getUpdates request; make sure that only one bot instance is running
2025-07-11 02:44:58,524 - telegram.ext.Application - ERROR - No error handlers are registered, logging exception.
Traceback (most recent call last):
  File "/usr/local/lib/python3.9/site-packages/telegram/ext/_application.py", line 1298, in process_update
    await coroutine
  File "/usr/local/lib/python3.9/site-packages/telegram/ext/_handlers/conversationhandler.py", line 842, in handle_update
    new_state: object = await handler.handle_update(
  File "/usr/local/lib/python3.9/site-packages/telegram/ext/_handlers/basehandler.py", line 158, in handle_update
    return await self.callback(update, context)
  File "/root/my_telegram_bot/isegelbot/main.py", line 769, in handle_navigation_callback
    return await replay_function(query, context)
  File "/root/my_telegram_bot/isegelbot/main.py", line 813, in _replay_ask_contact_method
    await description(query.message, context)
  File "/root/my_telegram_bot/isegelbot/main.py", line 372, in description
    context.user_data["description"] = update.message.text
AttributeError: 'Message' object has no attribute 'message'
2025-07-11 03:57:22,294 - __main__ - INFO - Yeni ilan e≈üle≈ütiriliyor (Esnek E≈üle≈ütirme) -> Pozisyon: 'Gayrimenkul Satƒ±≈ü Danƒ±≈ümanƒ±', ≈ûehir: 'ankara'
2025-07-11 03:57:22,311 - __main__ - INFO - Puanlar barajƒ± ge√ßemedi: {'Kar≈üƒ±lama Hostesi/Sekreter': 30}
2025-07-11 03:57:22,457 - __main__ - INFO - Sessiz ilan g√∂nderildi. Chat ID: -1002421814809, Thread ID: None
2025-07-11 03:57:22,650 - __main__ - INFO - Sessiz ilan g√∂nderildi. Chat ID: -1002633973054, Thread ID: None
2025-07-11 07:43:57,086 - __main__ - INFO - Yeni ilan e≈üle≈ütiriliyor (Esnek E≈üle≈ütirme) -> Pozisyon: 'WHATSAPPTAN YAZINIZ ARAMALARA CEVAP VERƒ∞LMEYECEKTƒ∞R.!!!! ( telefon yoƒüunluƒüu sebebiyle  )  

BOSTANCIDA  BULUNAN MC DONALDS BURGER Kƒ∞NG VE POPEYES ≈ûUBELERƒ∞Mƒ∞Z ƒ∞√áƒ∞N KAPANI≈û TEMƒ∞ZLƒ∞ƒûƒ∞ VE BULA≈ûIK√áI ARAMAKTAYIZ. L√úTFEN TECR√úBELƒ∞ ARKADA≈ûLAR ƒ∞LETƒ∞≈ûƒ∞ME GE√áSƒ∞N. 

Ak≈üam 10 sabah 6 √ßalƒ±≈üma saati 

Servisimiz yoktur yakƒ±n LOKASYONDAKƒ∞ arkada≈ülar yazabilirler. 

Maa≈ü dolgundur. 
Sgk yemek mevcuttur. 

ƒ∞leti≈üim i√ßin. WHATSAPP 

ISRARLA ARAMAYINIZ WHATSAPPTAN YAZINIZ. 
Yakup 
05315692716 
S√ºleyman 
+90 541 623 84 96', ≈ûehir: 'istanbul'
2025-07-11 07:43:57,173 - __main__ - INFO - Puanƒ± ge√ßen konular (sƒ±ralƒ±): [('Bula≈üƒ±k√ßƒ±', 120)]
2025-07-11 07:43:57,173 - __main__ - INFO - ≈ûehir e≈üle≈ümesi ba≈üarƒ±lƒ±: 'istanbul' ≈üehri i√ßin 'istanbul' anahtarƒ± bulundu.
2025-07-11 07:43:57,174 - __main__ - INFO - ‚úÖ BA≈ûARILI KATEGORƒ∞ E≈ûLE≈ûMESƒ∞: 'Bula≈üƒ±k√ßƒ±' -> 'Bula≈üƒ±k√ßƒ±' (ID: 22)
2025-07-11 07:43:57,400 - __main__ - INFO - Sessiz ilan g√∂nderildi. Chat ID: -1002421814809, Thread ID: None
2025-07-11 07:43:57,670 - __main__ - INFO - Sessiz ilan g√∂nderildi. Chat ID: -1002673178372, Thread ID: None
2025-07-11 07:43:57,993 - __main__ - INFO - Sessiz ilan g√∂nderildi. Chat ID: -1002673178372, Thread ID: 22
